<?xml version="1.0"?>

<!-- Robotica A -->
<!-- Trabalho 1 -->
<!-- Alecson Didone, Romulo Raffin e Samuel Gastal -->

<robot name="quanser">

	<link name="bloco">
		<visual>
			<origin xyz="0 0 .12" rpy="0 0 0"/>
      			<geometry>
        			<box size="0.12 0.2 0.24"/>
 			</geometry>
			<material name="black">
				<color rgba="0 0 0 0.5"/>
			</material>
		</visual>
		<collision>
			<origin xyz="0 0 .12" rpy="0 0 0"/>
			<geometry>
				<box size="0.12 0.2 0.24"/>
			</geometry>
		</collision>
		<inertial>
			<origin xyz="0.0 0.0 0.12" rpy="0 0 0" />
			<mass value="0.2" />
			<inertia ixx="0.3" ixy="0.3" ixz="0.3" iyy="0.3" iyz="0.3" izz="0.3" />
		</inertial>
	</link>

	<link name="link1">
		<visual>
			<origin xyz="0 0 0" rpy="0 0 0"/>
      			<geometry>
        			<box size="0.343 0.08 0.05"/>
 			</geometry>
			<material name="black">
				<color rgba="0 0 0 0.5"/>
			</material>
		</visual>
		<collision>
			<origin xyz="0 0 0" rpy="0 0 0"/>
			<geometry>
        			<box size="0.0 0.0 0.0"/>
			</geometry>
		</collision>
		<inertial>
			<origin xyz="0.0 0.0 0.0" rpy="0 0 0" />
			<mass value="0.01" />
			<inertia ixx="0.3" ixy="0.3" ixz="0.3" iyy="0.3" iyz="0.3" izz="0.3" />
		</inertial>
	</link>

	<link name="link2">
		<visual>
			<origin xyz="0 0 0" rpy="0 0 0"/>
      			<geometry>
        			<box size="0.267 0.08 0.05" />
 			</geometry>
			<material name="black">
				<color rgba="0 0 0 0.5"/>
			</material>
		</visual>
		<collision>
			<origin xyz="0 0 0" rpy="0 0 0"/>
			<geometry>
        			<box size="0.267 0.08 0.05" />
			</geometry>
		</collision>
		<inertial>
			<origin xyz="0 0 0" rpy="0 0 0" />
			<mass value="0.01" />
			<inertia ixx="0.3" ixy="0.3" ixz="0.3" iyy="0.3" iyz="0.3" izz="0.3" />
		</inertial>
	</link>

	<joint name="joint_bloco_link1" type="revolute">
		<origin xyz="0.2315 0 0.12" rpy="0 0 0" />
		<parent link="bloco" />
		<child link="link1" />
		<limit effort="30" velocity="1.0" lower="-1.57" upper="1.57" />
	</joint>

	<joint name="joint_link1_link2" type="revolute">
		<origin xyz="0.305 0.0 0." rpy="0 0 0" />
		<parent link="link1" />
		<child link="link2" />
		<limit effort="30" velocity="1.0" lower="-1.57" upper="1.57" />
	</joint>

	<transmission name="joint1_transmission">
		<type>transmission_interface/SimpleTransmission</type>
		<joint name="joint_bloco_link1">
			<hardwareInterface>EffortJointInterface</hardwareInterface>
		</joint>
		<actuator name="motor1">
			<hardwareInterface>EffortJointInterface</hardwareInterface>
			<mechanicalReduction>1</mechanicalReduction>
		</actuator>
	</transmission>
<transmission name="joint2_transmission">
		<type>transmission_interface/SimpleTransmission</type>
		<joint name="joint_link1_link2">
			<hardwareInterface>EffortJointInterface</hardwareInterface>
		</joint>
		<actuator name="motor2">
			<hardwareInterface>EffortJointInterface</hardwareInterface>
			<mechanicalReduction>1</mechanicalReduction>
		</actuator>
	</transmission>

	<gazebo>
		<plugin name="gazebo_ros_control" filename="libgazebo_ros_control.so">
			<robotNamespace>/quanser</robotNamespace>
			<controlPeriod>0.001</controlPeriod>
		</plugin>
	</gazebo>

	<gazebo reference="bloco">
		<material>Gazebo/Black</material>
	</gazebo>

	<gazebo reference="link1">
		<material>Gazebo/Black</material>
	</gazebo>

	<gazebo reference="link2">
		<material>Gazebo/Black</material>
	</gazebo>
</robot>
